Workbook

Sheet Executive Summary
A1: CITY OF CHICAGO — DEPARTMENT OF PROCUREMENT SERVICES
A2: Prepared by James Kirby III, CSCP, MS-SCM | Senior Buyer & Procurement Research Analyst | Department of Procurement Services
A3: Analysis Date: April 06, 2026
A5: QUICK WIN CONSOLIDATION SAVINGS MODEL
A6: Exhibit B Requisition Data — January 2021 through January 2026
A8: SUMMARY METRICS
A9: Metric | B9: Value
A10: Total Categories Analyzed | B10: 2
A11: Total 5-Year Spend | B11: ='Consolidation Savings Model'!B67
A12: Combined Annual Savings | B12: ='Consolidation Savings Model'!B70
A13: Combined 3-Year Projected Value | B13: ='Consolidation Savings Model'!B71
A15: CATEGORY DETAIL
A16: Category | B16: 5-Year Total Spend | C16: Vendor Count | D16: Department Count | E16: Solicitation Status | F16: 3-Year Projected Value
A17: Fencing & Guardrail | B17: ='Consolidation Savings Model'!B26 | C17: 2 | D17: 6 | E17: Phase A (Req# 596048) | F17: ='Consolidation Savings Model'!B30
A18: Janitorial & Cleaning Services | B18: ='Consolidation Savings Model'!B55 | C18: 3 | D18: 3 | E18: Phase A (Req# 624331) | F18: ='Consolidation Savings Model'!B59
A19: COMBINED TOTAL | B19: =SUM(B17:B18) | F19: =SUM(F17:F18)
A21: RECOMMENDATION
A22: Both categories are in Phase A — Spec Development with no solicitation issued and no contract awarded. This represents an ideal window for competitive solicitation. A consolidated RFP for each category would leverage citywide volume to achieve estimated savings of $306,502 over 3 years. Recommend proceeding to Phase B — Solicitation for both categories immediately.
A24: Savings Chain: 5-Year Total ÷ 5 = Annual Run Rate × 85% = Addressable Spend × 10% = Annual Savings × 3 = 3-Year Projected Value

Sheet Consolidation Savings Model
A1: CITY OF CHICAGO — DEPARTMENT OF PROCUREMENT SERVICES
A2: Prepared by James Kirby III, CSCP, MS-SCM | Senior Buyer & Procurement Research Analyst | Department of Procurement Services
A3: Analysis Date: April 06, 2026
A5: CATEGORY: FENCING & GUARDRAIL
A7: Vendor Breakdown
A8: Vendor Name | B8: Total Spend | C8: Transaction Count | D8: Department Count | E8: Notes
A9: INDUSTRIAL FENCE INC. | B9: 4801076.1 | C9: 87 | D9: 6
A10: FENCE MASTERS, INC | B10: 10955.35 | C10: 2 | D10: 2
A11: VENDOR SUBTOTAL | B11: =SUM(B9:B10) | C11: =SUM(C9:C10)
A13: Department Breakdown
A14: Department Name | B14: Total Spend
A15: Fire Dept | B15: 1471850.6
A16: Aviation | B16: 1377814
A17: Water Mgmt | B17: 1103130.9
A18: Fleet | B18: 479930.55
A19: Transportation | B19: 323180.04
A20: Emergency Mgmt | B20: 56125.37
A21: DEPARTMENT SUBTOTAL | B21: =SUM(B15:B20)
A23: CROSS-CHECK: Vendor Total − Department Total | B23: =B11-B21 | E23: Must equal $0.00
A25: SAVINGS CHAIN CALCULATION
A26: 5-Year Total Spend | B26: =B11 | E26: Verified vendor subtotal
A27: Annual Run Rate | B27: =B26/5 | E27: 5-Year Total ÷ 5
A28: Addressable Spend (85%) | B28: =B27*0.85 | E28: Annual × 85% (15% already optimized)
A29: Annual Savings (10%) | B29: =B28*0.10 | E29: Addressable × 10% (moderate savings rate)
A30: 3-Year Projected Value | B30: =B29*3 | E30: Annual Savings × 3 years
A32: Solicitation Status | B32: Phase A — Spec Development (Req# 596048)
A33: Contract Status | B33: No solicitation issued. No contract awarded.
A36: CATEGORY: JANITORIAL & CLEANING SERVICES
A38: Vendor Breakdown
A39: Vendor Name | B39: Total Spend | C39: Transaction Count | D39: Department Count | E39: Notes
A40: DAYSPRING PROFESSIONAL JANITOR | B40: 1056399 | C40: 9 | D40: 2
A41: LUSE ENVIRONMENTAL SERVICES, INC. | B41: 139859.5 | C41: 6 | D41: 2
A42: SET ENVIRONMENTAL INC | B42: 1547.44 | C42: 2 | D42: 1
A43: VENDOR SUBTOTAL | B43: =SUM(B40:B42) | C43: =SUM(C40:C42)
A45: Department Breakdown
A46: Department Name | B46: Total Spend
A47: Fleet | B47: 1155352.6
A48: Public Health | B48: 40905.82
A49: Animal Care | B49: 1547.44
A50: DEPARTMENT SUBTOTAL | B50: =SUM(B47:B49)
...
