Workbook

Sheet Executive Summary
A1: MAVERICK SPEND CONVERSION TRACKER
A2: Did non-contract (maverick) Exhibit B spend move onto an awarded contract? | January 5, 2026 to August 20, 2026
B4: THE BOTTOM LINE
B5: Of 175 distinct sourcing efforts representing $53,461,392 of Exhibit B spend, 8 can be independently verified as having moved onto an awarded contract during the period. Departments self-reported 33 as awarded. The gap between the claim and the evidence is the single most important finding in this analysis.
B9: CONVERSION SCORECARD
B10: Measure | C10: Requisitions | D10: Spend | E10: Basis
B11: Total Exhibit B spend in period | C11: =COUNTA('EB Detail'!$A$2:$A$731) | D11: =SUM('EB Detail'!$F$2:$F$731) | E11: Every Exhibit B requisition in the source file
B12: Expected to convert (new contract requested) | C12: =COUNTIF('EB Detail'!$W$2:$W$731,"Yes") | D12: =SUMIF('EB Detail'!$W$2:$W$731,"Yes",'EB Detail'!$F$2:$F$731) | E12: Excludes one-time purchases, invoice reconciliation, bid protests
B13: Self-reported by department as awarded | C13: =COUNTIF('EB Detail'!$K$2:$K$731,"Yes") | D13: =SUMIF('EB Detail'!$K$2:$K$731,"Yes",'EB Detail'!$F$2:$F$731) | E13: Department's own 'Contract Awarded?' answer - unverified
B14: VERIFIED converted to an awarded contract | C14: =COUNTIF('EB Detail'!$U$2:$U$731,"Yes") | D14: =SUMIF('EB Detail'!$U$2:$U$731,"Yes",'EB Detail'!$F$2:$F$731) | E14: ID or vendor+commodity link to the awarded file, award dated after the Exhibit B
B15: of which COMPETITIVELY awarded (Bid/RFQ/RFP) | C15: =COUNTIFS('EB Detail'!$U$2:$U$731,"Yes",'EB Detail'!$T$2:$T$731,"Yes") | D15: =SUMIFS('EB Detail'!$F$2:$F$731,'EB Detail'!$U$2:$U$731,"Yes",'EB Detail'!$T$2:$T$731,"Yes") | E15: The procurement-correct outcome
B16: of which non-competitive (sole source/emergency) | C16: =COUNTIFS('EB Detail'!$U$2:$U$731,"Yes",'EB Detail'!$T$2:$T$731,"No") | D16: =SUMIFS('EB Detail'!$F$2:$F$731,'EB Detail'!$U$2:$U$731,"Yes",'EB Detail'!$T$2:$T$731,"No") | E16: Exited Exhibit B but did NOT go competitive
B17: Reverse leakage (Exhibit B filed AFTER award) | C17: =COUNTIF('EB Detail'!$V$2:$V$731,"Yes") | D17: =SUMIF('EB Detail'!$V$2:$V$731,"Yes",'EB Detail'!$F$2:$F$731) | E17: Contract existed - spend should have ridden it
B18: Still open / no linkage found | C18: =COUNTIF('EB Detail'!$N$2:$N$731,"E") | D18: =SUMIF('EB Detail'!$N$2:$N$731,"E",'EB Detail'!$F$2:$F$731) | E18: No matching award in the supplied file - see Limitations
B20: CONVERSION RATE
B21: Verified conversion rate - requisitions, as % of those expected to convert | C21: =IFERROR(COUNTIFS('EB Detail'!$W$2:$W$731,"Yes",'EB Detail'!$U$2:$U$731,"Yes")/C12,0)
B22: Verified conversion rate - dollars, as % of spend expected to convert | C22: =IFERROR(SUMIFS('EB Detail'!$F$2:$F$731,'EB Detail'!$W$2:$W$731,"Yes",'EB Detail'!$U$2:$U$731,"Yes")/D12,0)
B23: Competitive conversion rate - dollars, as % of spend expected to convert | C23: =IFERROR(SUMIFS('EB Detail'!$F$2:$F$731,'EB Detail'!$W$2:$W$731,"Yes",'EB Detail'!$U$2:$U$731,"Yes",'EB Detail'!$T$2:$T$731,"Yes")/D12,0)
B24: Department claims that verify (of rows marked 'Contract Awarded? = Yes') | C24: =IFERROR(COUNTIFS('EB Detail'!$K$2:$K$731,"Yes",'EB Detail'!$U$2:$U$731,"Yes")/COUNTIF('EB Detail'!$K$2:$K$731,"Yes"),0)
B25: Verified conversions the department did NOT flag as awarded | C25: =COUNTIFS('EB Detail'!$K$2:$K$731,"No",'EB Detail'!$U$2:$U$731,"Yes")
B27: WHAT LEADERSHIP NEEDS TO KNOW
B28: 1. The claim does not survive verification
B29: Departments marked 48 requisitions ($9,997,088) as having an awarded contract. Only 6 of those verify against the awarded contract file. Of the 25 contract numbers departments supplied, only 2 appear anywhere in the actual award data. The error runs both ways: 16 requisitions did convert to an awarded contract but were never flagged as awarded. Exhibit B status is not being maintained.
B32: 2. Exhibit B spend is concentrated in a handful of stalled sourcing efforts
B33: The single largest - There was an active contract for Comprehensive Custodial Services for Zones 1, 2, and 4, w - accounts for $16,275,951 across 49 requisitions and is still in 'A. Specification Development Phase'. Counting requisitions instead of sourcing efforts hides this.
B36: 3. Near-term relief is real and measurable
B37: 25 requisitions worth $8,587,385 sit in Recommendation of Award or Signature Cycle - one step from contract. These convert in the next 60-90 days without new intervention.
B40: 4. The long tail will not clear this year
B41: 357 requisitions worth $23,024,247 are still in Specification Development. On normal cycle times these are 12+ months from award and will keep generating Exhibit B activity.
B44: 5. Exiting Exhibit B is not the same as going competitive
B45: Of the awarded contracts in this period, only 53 of 100 were competitively procured (Bid/RFQ/RFP). Some Exhibit B spend exited into sole-source and emergency awards - off the exception report, but not competitively sourced.
B48: 6. Reverse leakage is occurring
B49: 8 requisitions were filed as Exhibit B exceptions AFTER a contract had already been awarded for that scope. That spend should have ridden the contract.

Sheet Conversion Scorecard
A1: CONVERSION SCORECARD BY SOURCING EFFORT
A2: One row per distinct sourcing effort (the pending new-contract requisition), not per Exhibit B requisition. This is the correct unit of analysis.
A4: Sourcing Effort | B4: Description | C4: Lead Department | D4: Exhibit B Vendor | E4: Requisitions | F4: Depts | G4: Exhibit B Spend | H4: Procurement Phase | I4: Status | J4: Evidence Tier | K4: Awarded Contract | L4: Award Type
A5: RX624331 | B5: There was an active contract for Comprehensive Custodial Services for Zones 1, 2, and 4, which expire on February 13, 2026. 2FM previously submitted a | C5: DEPARTMENT OF FLEET AND FACILITY MANAGEMENT | D5: ABM INDUSTRY GROUPS, LLC | E5: 49 | F5: 2 | G5: 16275951 | H5: A. Specification Development Phase | I5: Still open | J5: E
A6: VDALDRIDGE ELECTRIC | B6: PO 96175 Aldridge Electric Exhibit B $3,900,000.00 | C6: CHICAGO DEPARTMENT OF TRANSPORTATION | D6: ALDRIDGE ELECTRIC INC | E6: 1 | F6: 1 | G6: 3900000 | H6: E. ROA - (Recommendation of Award) | I6: Claimed awarded - UNVERIFIED | J6: E
A7: RX686938 | B7: Transfered from APRF No. 511278. Regular and emergency bus services at O'Hare Airport for January through March 2026 | C7: CHICAGO DEPARTMENT OF AVIATION | D7: DELAWARE CARS/T.R. HARMSEN CORP. J.V. | E7: 1 | F7: 1 | G7: 3276126.9 | H7: F. SC - (Signature Cycle) | I7: Still open | J7: E
A8: RX661351 | B8: Liquid Aluminum Sulfate (Iron Free) | C8: DEPARTMENT OF WATER MANAGEMENT | D8: USALCO | E8: 7 | F8: 1 | G8: 3248945.8 | H8: A. Specification Development Phase | I8: Still open | J8: E
A9: RX604388 | B9: Transfered from APRF No. 513665. Requesting a Direct Voucher - Exhibit B for O'Hare due to expired contract. Elevators,1-MOD/Final 7/27/26 nt | C9: CHICAGO DEPARTMENT OF AVIATION | D9: SCHINDLER ELEVATOR CORP | E9: 3 | F9: 1 | G9: 2596967.8 | H9: D. Solicitation Response Under Evaluation | I9: Still open | J9: E
A10: RX634792 | B10: PURCHASE OF BLACK AND BLUE MOBILE CARTS | C10: DEPARTMENT OF STREETS AND SANITATION | D10: CASCADE ENGINEERING, INC | E10: 4 | F10: 1 | G10: 2406381.5 | H10: C. Solicitation or Bidding Phase | I10: Still open | J10: E
A11: RX492778 | B11: Street and Parkway Restoration Central North Region | C11: DEPARTMENT OF WATER MANAGEMENT | D11: SUMIT CONSTRUCTION CO., INC. | E11: 2 | F11: 1 | G11: 1902848.1 | H11: H. One Time Purchase | I11: Claimed awarded - UNVERIFIED | J11: C | K11: 385131 | L11: BID
A12: RX596048 | B12: FFIB Industrial Fence $578,668.60 | C12: CHICAGO FIRE DEPARTMENT | D12: INDUSTRIAL FENCE INC. | E12: 22 | F12: 3 | G12: 1061040.1 | H12: B. City Law Review | I12: Still open | J12: E
A13: RX492777 | B13: Street and Parkway Restoration North Region | C13: DEPARTMENT OF WATER MANAGEMENT | D13: SUMIT CONSTRUCTION CO., INC. | E13: 1 | F13: 1 | G13: 938950.36 | H13: H. One Time Purchase | I13: Claimed awarded - UNVERIFIED | J13: C | K13: 385131 | L13: BID
A14: RX650171 | B14: PROVIDE AN ELECTRICIANCUSTOMER, TROUBLESHOOTACCURPRESS AND BACK GAUGE FOROPERATION | C14: CHICAGO DEPARTMENT OF TRANSPORTATION | D14: PALM ELECTRIC COMPANY | E14: 10 | F14: 3 | G14: 891296.67 | H14: B. City Law Review | I14: Still open | J14: E
A15: RX682957 | B15: There is currently no active contract for Integrated Pest Management. The vendor chose not to extend beyond the May 29, 2025 expiration date. 2FM subm | C15: DEPARTMENT OF FLEET AND FACILITY MANAGEMENT | D15: ABC Humane Wildlife Control & Prevention, Inc. | E15: 21 | F15: 2 | G15: 824511.78 | H15: A. Specification Development Phase | I15: Still open | J15: E
A16: RX492772 | B16: Street and Parkway and Restoration Project No. 19-623 Central South Region | C16: DEPARTMENT OF WATER MANAGEMENT | D16: MAT CONSTRUCTION | E16: 1 | F16: 1 | G16: 687712.68 | H16: H. One Time Purchase | I16: Claimed awarded - UNVERIFIED | J16: E
A17: VDPALM ELECTRIC | B17: Invoice# I1257961 | C17: CHICAGO DEPARTMENT OF AVIATION | D17: PALM ELECTRIC COMPANY | E17: 1 | F17: 1 | G17: 684760.97 | H17: C. Solicitation or Bidding Phase | I17: Still open | J17: E
A18: RX590958 | B18: WB/MM/INVOICE#598412/$1221.66 | C18: DEPARTMENT OF FLEET AND FACILITY MANAGEMENT | D18: JACOB PRESS' SONS INC | E18: 35 | F18: 1 | G18: 678952.98 | H18: B. City Law Review | I18: Still open | J18: E
A19: VDATLAS TECHNICAL CONSULTANTS | B19: PO 114541 Exhibit B for Atlas Technical Consultants LLC | C19: CHICAGO DEPARTMENT OF TRANSPORTATION | D19: Atlas Technical Consultants LLC | E19: 1 | F19: 1 | G19: 503441.06 | H19: G. Not Applicable (Office Depot use Only) | I19: Claimed awarded - UNVERIFIED | J19: E
A20: RX425669 | B20: R4 Services / JK / EJ / INV # A410397 / $42,446.68 / June 2026 | C20: DEPARTMENT OF FLEET AND FACILITY MANAGEMENT | D20: R4 SERVICES, LLC. | E20: 8 | F20: 1 | G20: 484042.33 | H20: E. ROA - (Recommendation of Award) | I20: Still open | J20: E
A21: RX690281 | B21: TB/AH/10 INVOICES/$348,811.34 | C21: DEPARTMENT OF FLEET AND FACILITY MANAGEMENT | D21: SPEEDY GONZALEZ LANDSCAPING INC | E21: 5 | F21: 1 | G21: 460263.55 | H21: C. Solicitation or Bidding Phase | I21: Still open | J21: E
A22: VDARLINGTON GLASS MIRROR | B22: #5 Invoices $242,660.23 Transferred from APRF No. 505880. Replace broken glass at Rotunda, H&R plant, T3 UL vestibule 3H, and bullet resistant pMOD | C22: CHICAGO DEPARTMENT OF AVIATION | D22: ARLINGTON GLASS & MIRROR | E22: 3 | F22: 1 | G22: 456128.15 | H22: B. City Law Review | I22: Still open | J22: E
A23: VDP R STREICH SONS | B23: Transferred from APRF No. 511689. ONE TIME PURCHASE OF TWENTY-FOUR (24) MOBILE COLUMN HOISTS WITH EXTENSION KITS1-MOD/Final 4/16/26 kf | C23: CHICAGO DEPARTMENT OF AVIATION | D23: P. R. STREICH & SONS | E23: 2 | F23: 1 | G23: 404724.23 | H23: H. One Time Purchase | I23: Still open | J23: E
A24: RX693525 | B24: VARIOUS STREET SIGN MAKING SUPPLIES | C24: CHICAGO DEPARTMENT OF TRANSPORTATION | D24: RI-DEL MFG. INC. | E24: 4 | F24: 1 | G24: 383274.22 | H24: A. Specification Development Phase | I24: Still open | J24: E
A25: RX596443 | B25: Landscape Maintenance Services | C25: CHICAGO DEPARTMENT OF TRANSPORTATION | D25: A SAFE HAVEN FOUNDATION | E25: 9 | F25: 2 | G25: 380345.75 | H25: B. City Law Review | I25: Still open | J25: E
A26: VDFLOWERS COMMUNICATIONS | B26: Emergency Preparedness Kits | C26: CHICAGO DEPARTMENT OF PUBLIC HEALTH | D26: FLOWERS COMMUNICATIONS GROUP | E26: 3 | F26: 1 | G26: 372418 | H26: H. One Time Purchase | I26: Still open | J26: E
A27: RX493564 | B27: Sewer Construction | C27: DEPARTMENT OF WATER MANAGEMENT | D27: RELIABLE CONTRACTING AND EQUIPMENT COMPANY | E27: 1 | F27: 1 | G27: 363157.77 | H27: H. One Time Purchase | I27: Still open | J27: C | K27: 383808 | L27: BID
A28: RX607835 | B28: Current Spec 127930's Scope of services for this Exhibit B is outside of the current contract. Additional language was added to the new Specification | C28: DEPARTMENT OF FLEET AND FACILITY MANAGEMENT | D28: WISS, JANNEY, ELSTNER, & ASSOCIATES, INC. | E28: 7 | F28: 1 | G28: 353043.77 | H28: H. One Time Purchase | I28: Still open | J28: E
A29: RX605613 | B29: Invoice# 5332152783 Maintenance of the Supervisory Monitoring System & Fire Alarm System for October 2025 Monthly Service | C29: CHICAGO DEPARTMENT OF AVIATION | D29: SIEMENS INDUSTRY INC. 01 | E29: 1 | F29: 1 | G29: 347623.41 | H29: E. ROA - (Recommendation of Award) | I29: Claimed awarded - UNVERIFIED | J29: E
A30: RX511569 | B30: WATER - DRINKING | C30: DEPARTMENT OF STREETS AND SANITATION | D30: BLUETRITON BRANDS INC | E30: 9 | F30: 2 | G30: 331645.87 | H30: A. Specification Development Phase | I30: Claimed awarded - UNVERIFIED | J30: E
A31: RX746444 | B31: TARP - SALT TARPING | C31: DEPARTMENT OF STREETS AND SANITATION | D31: CHICAGO UNITED INDUSTRIES, LTD | E31: 1 | F31: 1 | G31: 327473.06 | H31: A. Specification Development Phase | I31: Still open | J31: E
A32: VDELECTRONIC KNOWLEDGE INTERCH | B32: TIER 2 SUPPORT - QUANT 16 SERVICES | C32: CHICAGO DEPARTMENT OF PUBLIC HEALTH | D32: Electronic Knowledge Interchange | E32: 5 | F32: 1 | G32: 306000 | H32: H. One Time Purchase | I32: Still open | J32: E
A33: RX710856 | B33: TB/INV#9008/$13,057.00 | C33: DEPARTMENT OF FLEET AND FACILITY MANAGEMENT | D33: CAR WASH PARTNERS INC | E33: 34 | F33: 1 | G33: 287936.99 | H33: A. Specification Development Phase | I33: Still open | J33: E
A34: RX724184 | B34: Hastings Air-Energy 1033282 B JS/ JG/ Invoice No. O38604D105/ $56,691.64/ April / Exhaust System Maint | C34: DEPARTMENT OF FLEET AND FACILITY MANAGEMENT | D34: HASTINGS AIR ENERGY CONTROL | E34: 5 | F34: 1 | G34: 278751.49 | H34: A. Specification Development Phase | I34: Claimed awarded - UNVERIFIED | J34: E
A35: RX659422 | B35: BOARD UP SERVICES | C35: DEPARTMENT OF BUILDINGS | D35: A & D PROPERTY SERVICES, INC. | E35: 5 | F35: 1 | G35: 277500 | H35: A. Specification Development Phase | I35: Still open | J35: E
A36: RX608757 | B36: Omicron CityKey Annual Licensing | C36: OFFICE OF CITY CLERK | D36: OMICRON TECHNOLOGY SOLUTIONS LLC | E36: 3 | F36: 1 | G36: 263800.02 | H36: B. City Law Review | I36: Still open | J36: E
A37: RX628102 | B37: Bella Bagno Inc is removing and installing carpet at the Bucktown/Wicker Park Branch Library. The labor services are outside of the contract prevue, a | C37: DEPARTMENT OF FLEET AND FACILITY MANAGEMENT | D37: BELLA BAGNO INC | E37: 2 | F37: 1 | G37: 260516.76 | H37: D. Solicitation Response Under Evaluation | I37: Claimed awarded - UNVERIFIED | J37: E
A38: VDSUNBELT STAFFING | B38: Sunbelt Outstanding Invoices | C38: CHICAGO DEPARTMENT OF PUBLIC HEALTH | D38: SUNBELT STAFFING LLC | E38: 2 | F38: 1 | G38: 247286 | H38: F. SC - (Signature Cycle) | I38: Still open | J38: E
A39: RX622326 | B39: Perform 2025 annual planned maintenance on one Caterpillar chlorine emergency power generator and five MTU main plant power emergency generators | C39: DEPARTMENT OF WATER MANAGEMENT | D39: CHARLES EQUIPMENT ENERGY SYSTEMS LLC | E39: 17 | F39: 2 | G39: 231704.01 | H39: H. One Time Purchase | I39: Still open | J39: E
... A45: RX600854 | B45: There is currently no active contract for this type of paper. The items being purchased are not part of the current Murnane contract. The Department | C45: DEPARTMENT OF FLEET AND FACILITY MANAGEMENT | D45: MURNANE PAPER COMPANY | E45: 14 | F45: 3 | G45: 195550.45 | H45: A. Specification Development Phase | I45: Still open | J45: E
A46: RX663987 | B46: JK / CA / INV#6660-3816-1 / WO#2626297 | C46: DEPARTMENT OF FLEET AND FACILITY MANAGEMENT | D46: Boschung America, LLC | E46: 4 | F46: 1 | G46: 189750.66 | H46: B. City Law Review | I46: Claimed awarded - UNVERIFIED | J46: C | K46: 388473 | L46: REFERENCE CONTRACT
...

Sheet Confirmed Conversions
A1: CONFIRMED CONVERSIONS - EVIDENCE TRAIL
A2: Every row here is independently verified: linked to the awarded contract file by ID or vendor+commodity, with the award dated AFTER the Exhibit B request.
A4: Exhibit B Req# | B4: Exhibit B Date | C4: Department | D4: Description | E4: Exhibit B Spend | F4: Awarded Contract ID | G4: Awarded Vendor | H4: Award Date | I4: Procurement Type | J4: Competitive? | K4: Match Basis
A5: 728515 | B5: 46146 | C5: DEPARTMENT OF FLEET AND FACILITY MANAGEMENT | D5: 2FM currently holds two helicopter maintenance contracts; however, the Bell 407 and 429 aircraft are not covered under e | E5: 89734.76 | F5: 386844 | G5: Helicopters, Inc. | H5: 46203 | I5: EMERGENCY | J5: No | K5: Requisition ID link: Exhibit B new-contract RX = awarded REQ
A6: 718284 | B6: 46097 | C6: DEPARTMENT OF FLEET AND FACILITY MANAGEMENT | D6: 2FM currently holds two helicopter maintenance contracts, however the Bell 407s and 429 aircraft are not under either co | E6: 18935.29 | F6: 386844 | G6: Helicopters, Inc. | H6: 46203 | I6: EMERGENCY | J6: No | K6: Requisition ID link: Exhibit B new-contract RX = awarded REQ
A7: 710068 | B7: 46048 | C7: DEPARTMENT OF FLEET AND FACILITY MANAGEMENT | D7: Helicopter 10633647 A JS/ BJ/ 6-Invoices/ $18,010.22/ PD911Z/ WO 2603623/ ASR | E7: 18010.22 | F7: 386844 | G7: Helicopters, Inc. | H7: 46203 | I7: EMERGENCY | J7: No | K7: Requisition ID link: Exhibit B new-contract RX = awarded REQ
A8: 739971 | B8: 46216 | C8: CHICAGO DEPARTMENT OF AVIATION | D8: 3 Invoices forACCT#1750627 Weather Augment Forecasting Services: 210-00278025 Period: 3/1/2026-3/31/2026; 210-00267261 P | E8: 9315 | F8: 381309 | G8: MURRAY & TRETTEL INC | H8: 46229 | I8: BID | J8: Yes | K8: Requisition ID link: Exhibit B new-contract RX = awarded REQ
A9: 711517 | B9: 46052 | C9: DEPARTMENT OF FLEET AND FACILITY MANAGEMENT | D9: DCASE submitted a new contract request for RENTAL AND MAINTENANCE OF PORTABLE CHEMICAL TOILETS, SINKS, WASTE WATER BARRE | E9: 7750 | F9: 381051 | G9: Service Sanitation Inc. | H9: 46203 | I9: BID | J9: Yes | K9: Vendor match + commodity overlap (similarity 0.64)
A10: 711510 | B10: 46052 | C10: DEPARTMENT OF FLEET AND FACILITY MANAGEMENT | D10: DCASE submitted a new contract request for RENTAL AND MAINTENANCE OF PORTABLE CHEMICAL TOILETS, SINKS, WASTE WATER BARRE | E10: 6700 | F10: 381051 | G10: Service Sanitation Inc. | H10: 46203 | I10: BID | J10: Yes | K10: Vendor match + commodity overlap (similarity 0.64)
A11: 716858 | B11: 46080 | C11: DEPARTMENT OF WATER MANAGEMENT | D11: SERVICE SANTATION REQ#613315. DCASE IS THE LEAD DEPARTMENT AND THE REQ WAS SENT TO DPS FOR A new contract on 8/13/2024 ( | E11: 5917 | F11: 381051 | G11: Service Sanitation Inc. | H11: 46203 | I11: BID | J11: Yes | K11: Requisition ID link: Exhibit B new-contract RX = awarded REQ
A12: 738810 | B12: 46212 | C12: CHICAGO DEPARTMENT OF PUBLIC HEALTH | D12: Consulting Fee June 2026 | E12: 3819.14 | F12: 386925 | G12: INTEGRATED SOLUTIONS CONSULTING CORPORATION | H12: 46220 | I12: SOLE SOURCE | J12: No | K12: Requisition ID link: Exhibit B new-contract RX = awarded REQ
A13: 730529 | B13: 46161 | C13: DEPARTMENT OF FLEET AND FACILITY MANAGEMENT | D13: TB/MM/INVOICE #Q25143/$3458.74 | E13: 3458.74 | F13: 386844 | G13: Helicopters, Inc. | H13: 46203 | I13: EMERGENCY | J13: No | K13: Requisition ID link: Exhibit B new-contract RX = awarded REQ
A14: 734145 | B14: 46177 | C14: CHICAGO DEPARTMENT OF PUBLIC HEALTH | D14: Hosting Fee | E14: 2499 | F14: 386925 | G14: INTEGRATED SOLUTIONS CONSULTING CORPORATION | H14: 46220 | I14: SOLE SOURCE | J14: No | K14: Requisition ID link: Exhibit B new-contract RX = awarded REQ
A15: 716927 | B15: 46080 | C15: CHICAGO DEPARTMENT OF AVIATION | D15: #2 Invoices $2,394.34 2025 FAA 139 Regulatory Compliance- Annual calibration of 3 decelerometers and Chargers equipmen | E15: 2394.34 | F15: 375509 | G15: Halliday Technologies | H15: 46106 | I15: BID | J15: Yes | K15: Requisition ID link: Exhibit B new-contract RX = awarded REQ
A16: 722898 | B16: 46119 | C16: CHICAGO DEPARTMENT OF PUBLIC HEALTH | D16: Consulting Fee February 2026Hosting Fee: February 2026Hosting Fee: January 2026 | E16: 1890.66 | F16: 386925 | G16: INTEGRATED SOLUTIONS CONSULTING CORPORATION | H16: 46220 | I16: SOLE SOURCE | J16: No | K16: Requisition ID link: Exhibit B new-contract RX = awarded REQ
... A26: 707665 | B26: 46058 | C26: CHICAGO DEPARTMENT OF AVIATION | D26: #4 Invoices $10,558.002025 Midway Snow Equipment & Snow Vehicles washing (Services 11/9, 11/10, 11/30 to 12/2 & 12/7 to | E26: 0 | F26: 375509 | G26: Halliday Technologies | H26: 46106 | I26: BID | J26: Yes | K26: Requisition ID link: Exhibit B new-contract RX = awarded REQ

Sheet Claimed vs Verified
A1: DEPARTMENT CLAIM vs INDEPENDENT VERIFICATION
A2: Rows the department marked 'Contract Awarded? = Yes'. The right-hand columns show what the awarded contract file actually supports.
A4: Exhibit B Req# | B4: Department | C4: Description | D4: Exhibit B Spend | E4: Contract # Claimed | F4: Claimed Number Check | G4: Evidence Tier | H4: Verdict | I4: Match Basis
A5: 730356 | B5: CHICAGO DEPARTMENT OF TRANSPORTATION | C5: PO 96175 Aldridge Electric Exhibit B $3,900,000.00 | D5: 3900000 | E5: Yes | F5: No number supplied | G5: E | H5: No supporting evidence | I5: No linkage found in awarded contract file
A6: 733323 | B6: DEPARTMENT OF WATER MANAGEMENT | C6: Street and Parkway Restoration cental North Region | D6: 1887067.6 | E6: 304519 | F6: NOT in award file | G6: C | H6: Weak / partial evidence | I6: Vendor name match only (similarity 0.00)
A7: 733294 | B7: DEPARTMENT OF WATER MANAGEMENT | C7: Street and Parkway Restoration North Region | D7: 938950.36 | E7: 305303 | F7: NOT in award file | G7: C | H7: Weak / partial evidence | I7: Vendor name match only (similarity 0.00)
A8: 734489 | B8: DEPARTMENT OF WATER MANAGEMENT | C8: Street and Parkway and Restoration Project No. 19-623 Central South Region | D8: 687712.68 | E8: 272862 | F8: NOT in award file | G8: E | H8: No supporting evidence | I8: No linkage found in awarded contract file
A9: 721945 | B9: CHICAGO DEPARTMENT OF TRANSPORTATION | C9: PO 114541 Exhibit B for Atlas Technical Consultants LLC | D9: 503441.06 | E9: 114541 | F9: NOT in award file | G9: E | H9: No supporting evidence | I9: No linkage found in awarded contract file
A10: 708701 | B10: CHICAGO DEPARTMENT OF AVIATION | C10: Invoice# 5332152783 Maintenance of the Supervisory Monitoring System & Fire Alarm System for October 2025 Mont | D10: 347623.41 | E10: 84871 | F10: NOT in award file | G10: E | H10: No supporting evidence | I10: No linkage found in awarded contract file
A11: 708713 | B11: CHICAGO DEPARTMENT OF AVIATION | C11: CDA requesting authorization to pay Siemens Industry Inc PO #84871, per service's procured in 2025 under activ | D11: 156240 | E11: 84871 | F11: NOT in award file | G11: E | H11: No supporting evidence | I11: No linkage found in awarded contract file
A12: 744818 | B12: CHICAGO DEPARTMENT OF TRANSPORTATION | C12: PO 180678 REL 295456 CSI 3000JV Exhibit B Invoice Reconciliation | D12: 156098.14 | E12: 309536 | F12: NOT in award file | G12: E | H12: No supporting evidence | I12: No linkage found in awarded contract file
A13: 738075 | B13: DEPARTMENT OF FLEET AND FACILITY MANAGEMENT | C13: Bella Bagno Inc is removing and installing carpet at the Bucktown/Wicker Park Branch Library. The labor servic | D13: 147666.41 | F13: No number supplied | G13: E | H13: No supporting evidence | I13: No linkage found in awarded contract file
A14: 734966 | B14: DEPARTMENT OF WATER MANAGEMENT | C14: Street and Parkway Repair Project NO. 19-625 North Region | D14: 143357.36 | E14: 272860 | F14: NOT in award file | G14: C | H14: Weak / partial evidence | I14: Vendor name match only (similarity 0.00)
A15: 737798 | B15: DEPARTMENT OF WATER MANAGEMENT | C15: Sewer Construction | D15: 121426.74 | E15: 297413 | F15: NOT in award file | G15: E | H15: No supporting evidence | I15: No linkage found in awarded contract file
A16: 725483 | B16: CHICAGO DEPARTMENT OF TRANSPORTATION | C16: Exhibit B Collins Engineers, Inc. PO 30193 $117,913.97 | D16: 117913.97 | E16: 319103 | F16: NOT in award file | G16: E | H16: No supporting evidence | I16: No linkage found in awarded contract file
A17: 710618 | B17: CHICAGO DEPARTMENT OF PUBLIC HEALTH | C17: Mpox/HIV consulting | D17: 115000 | E17: 225759 | F17: NOT in award file | G17: E | H17: No supporting evidence | I17: No linkage found in awarded contract file
A18: 707827 | B18: DEPARTMENT OF FLEET AND FACILITY MANAGEMENT | C18: Bella Bagno 1010329 D JS/ AO/ Invoice 130069/$ 112,850.35/ WO 5244306/ Legler | D18: 112850.35 | E18: Not awarded yet, still under DPS review. | F18: No number supplied | G18: E | H18: No supporting evidence | I18: No linkage found in awarded contract file
A19: 737175 | B19: CHICAGO ANIMAL CARE AND CONTROL | C19: VLI NEEDED FOR DEAD ANIMAL CREMATION SERVICES | D19: 80585.4 | E19: yes | F19: No number supplied | G19: E | H19: No supporting evidence | I19: No linkage found in awarded contract file
A20: 730922 | B20: DEPARTMENT OF FLEET AND FACILITY MANAGEMENT | C20: HASTINGS 1033282 B JS/ JG/ Invoice # O38604D104/ $78,693.06/ March/ Exhaust System Maint | D20: 78693.06 | E20: 112351 | F20: NOT in award file | G20: E | H20: No supporting evidence | I20: No linkage found in awarded contract file
A21: 727149 | B21: DEPARTMENT OF FLEET AND FACILITY MANAGEMENT | C21: Hastings 1033282 B JS/ JG/ Invoice # O38604D103/ $71,534.69/ February / Exhaust System Maintenance | D21: 71534.69 | E21: 112351 | F21: NOT in award file | G21: E | H21: No supporting evidence | I21: No linkage found in awarded contract file
A22: 711549 | B22: DEPARTMENT OF HUMAN RESOURCES | C22: EXHIBIT B - TALOGY PO 251333 INVOICES $67,689.70 | D22: 67689.7 | E22: 251333 | F22: NOT in award file | G22: E | H22: No supporting evidence | I22: No linkage found in awarded contract file
A23: 733531 | B23: DEPARTMENT OF FLEET AND FACILITY MANAGEMENT | C23: Hastings Air-Energy 1033282 B JS/ JG/ Invoice No. O38604D105/ $56,691.64/ April / Exhaust System Maint | D23: 56691.64 | E23: 112351 | F23: NOT in award file | G23: E | H23: No supporting evidence | I23: No linkage found in awarded contract file
A24: 741917 | B24: DEPARTMENT OF FLEET AND FACILITY MANAGEMENT | C24: 2FM has an active contract for Plymovent Exhaust Extraction Systems, PO 112351. 2FM submitted a request to ext | D24: 36953.65 | E24: 112351 | F24: NOT in award file | G24: E | H24: No supporting evidence | I24: No linkage found in awarded contract file
A25: 746580 | B25: DEPARTMENT OF FLEET AND FACILITY MANAGEMENT | C25: JK / CA / INV#6660-3816-1 / WO#2626297 | D25: 36815.66 | F25: No number supplied | G25: C | H25: Weak / partial evidence | I25: Vendor name match only (similarity 0.00)
A26: 746117 | B26: DEPARTMENT OF FLEET AND FACILITY MANAGEMENT | C26: TB/JG/INVOICE #O38604D106/$34,878.45 | D26: 34878.45 | E26: 112351 | F26: NOT in award file | G26: E | H26: No supporting evidence | I26: No linkage found in awarded contract file
A27: 719021 | B27: DEPARTMENT OF WATER MANAGEMENT | C27: FLEET AND FACILITY MANAGEMENT ("2FM") IS THE LEAD DEPARTMENT FOR PO 32909 INTEGRATED PEST MANAGEMENT SERVICES, | D27: 34562.66 | E27: 682957 | F27: NOT in award file | G27: E | H27: No supporting evidence | I27: No linkage found in awarded contract file
A28: 711554 | B28: DEPARTMENT OF HUMAN RESOURCES | C28: EXHIBIT B - MEDICAL/PHYSICAL EXAMS AND DRUG TESTING/LAB SERVICES - OCCUPATIONAL HEALTH CENTERS DBA CONCENTRA I | D28: 20353 | E28: 121696 | F28: NOT in award file | G28: E | H28: No supporting evidence | I28: No linkage found in awarded contract file
A29: 718284 | B29: DEPARTMENT OF FLEET AND FACILITY MANAGEMENT | C29: 2FM currently holds two helicopter maintenance contracts, however the Bell 407s and 429 aircraft are not under | D29: 18935.29 | E29: TBD | F29: No number supplied | G29: A | H29: VERIFIED | I29: Requisition ID link: Exhibit B new-contract RX = awarded REQ
A30: 710068 | B30: DEPARTMENT OF FLEET AND FACILITY MANAGEMENT | C30: Helicopter 10633647 A JS/ BJ/ 6-Invoices/ $18,010.22/ PD911Z/ WO 2603623/ ASR | D30: 18010.22 | E30: TBD | F30: No number supplied | G30: A | H30: VERIFIED | I30: Requisition ID link: Exhibit B new-contract RX = awarded REQ
A31: 733996 | B31: DEPARTMENT OF WATER MANAGEMENT | C31: Street and Parkway Restoration Central North Region | D31: 15780.52 | E31: 304519 | F31: NOT in award file | G31: C | H31: Weak / partial evidence | I31: Vendor name match only (similarity 0.07)
A32: 742847 | B32: CHICAGO DEPARTMENT OF TRANSPORTATION | C32: 31st Street Viaduct over Metra/ICRR - Exhibit B payment request for AECOM (PO #47573 - Rel 5) | D32: 13656.95 | E32: 47573 | F32: NOT in award file | G32: E | H32: No supporting evidence | I32: No linkage found in awarded contract file
A33: 746507 | B33: DEPARTMENT OF FAMILY AND SUPPORT SERVICES | C33: Exhibit B_$9865 | D33: 9865 | E33: 53096 | F33: NOT in award file | G33: E | H33: No supporting evidence | I33: No linkage found in awarded contract file
A34: 742855 | B34: DEPARTMENT OF FAMILY AND SUPPORT SERVICES | C34: Exhibit B_2 8160 | D34: 8160 | E34: 348927 | F34: Found in award file | G34: A | H34: Weak / partial evidence | I34: Contract number link: reported number = awarded PO
A35: 742832 | B35: DEPARTMENT OF FAMILY AND SUPPORT SERVICES | C35: Exhibit B_ 8160 | D35: 8160 | E35: 348927 | F35: Found in award file | G35: A | H35: Weak / partial evidence | I35: Contract number link: reported number = awarded PO
A36: 742887 | B36: DEPARTMENT OF FAMILY AND SUPPORT SERVICES | C36: Exhibit B_3_7644 | D36: 7644 | E36: 348927 | F36: Found in award file | G36: A | H36: Weak / partial evidence | I36: Contract number link: reported number = awarded PO
A37: 714146 | B37: DEPARTMENT OF WATER MANAGEMENT | C37: DCASE IS THE LEAD DEPARTMENT. REQ#613315 WAS SUBMITTED TO DPS ON 8/13/2024 FOR A NEW CONTRACT (BOARD DATE:09/1 | D37: 6427 | E37: 613315 | F37: Found in award file | G37: C | H37: Weak / partial evidence | I37: Vendor name match only (similarity 0.00)
A38: 718031 | B38: DEPARTMENT OF WATER MANAGEMENT | C38: A REQ#700212 HAS SUBMITED TO DPS FOR 181-DAY EXTENSION AND IS PENDING DOCUSIGN APPROVAL AS OF 2/9/26. A NEW CO | D38: 6325 | E38: 700212 | F38: NOT in award file | G38: C | H38: Weak / partial evidence | I38: Vendor name match only (similarity 0.00)
A39: 714112 | B39: DEPARTMENT OF WATER MANAGEMENT | C39: THIS SERVICE SANITATION ORDER NEEDED A NEW CONTRACT FOR THE PREVIOUS ONE HAS EXPIRED AND HAD BEEN WAITING FOR | D39: 6325 | E39: 613315 | F39: Found in award file | G39: C | H39: Weak / partial evidence | I39: Vendor name match only (similarity 0.00)
A40: 716858 | B40: DEPARTMENT OF WATER MANAGEMENT | C40: SERVICE SANTATION REQ#613315. DCASE IS THE LEAD DEPARTMENT AND THE REQ WAS SENT TO DPS FOR A new contract on 8 | D40: 5917 | E40: 613315 | F40: Found in award file | G40: A | H40: VERIFIED | I40: Requisition ID link: Exhibit B new-contract RX = awarded REQ
A41: 714132 | B41: CHICAGO DEPARTMENT OF PUBLIC HEALTH | C41: All In One Desktops | D41: 4815 | F41: No number supplied | G41: E | H41: No supporting evidence | I41: No linkage found in awarded contract file
...

Sheet Still Open - Ranked
A1: STILL-OPEN SOURCING EFFORTS RANKED BY SPEND AT RISK
A2: Maverick spend with no verified contract award. This is the work queue - clearing the top of this list removes the most Exhibit B activity.
A4: Rank | B4: Description | C4: Lead Department | D4: Requisitions | E4: Exhibit B Spend | F4: Cumulative | G4: Cum % | H4: Procurement Phase | I4: Status
A5: 1 | B5: There was an active contract for Comprehensive Custodial Services for Zones 1, 2, and 4, which expire on February 13, 2026. 2FM previously submitted a | C5: DEPARTMENT OF FLEET AND FACILITY MANAGEMENT | D5: 49 | E5: 16275951 | F5: 16275951 | G5: 0.30588548 | H5: A. Specification Development Phase | I5: Still open
A6: 2 | B6: PO 96175 Aldridge Electric Exhibit B $3,900,000.00 | C6: CHICAGO DEPARTMENT OF TRANSPORTATION | D6: 1 | E6: 3900000 | F6: 20175951 | G6: 0.37918095 | H6: E. ROA - (Recommendation of Award) | I6: Claimed awarded - UNVERIFIED
A7: 3 | B7: Transfered from APRF No. 511278. Regular and emergency bus services at O'Hare Airport for January through March 2026 | C7: CHICAGO DEPARTMENT OF AVIATION | D7: 1 | E7: 3276126.9 | F7: 23452078 | G7: 0.44075153 | H7: F. SC - (Signature Cycle) | I7: Still open
A8: 4 | B8: Liquid Aluminum Sulfate (Iron Free) | C8: DEPARTMENT OF WATER MANAGEMENT | D8: 7 | E8: 3248945.8 | F8: 26701024 | G8: 0.50181127 | H8: A. Specification Development Phase | I8: Still open
A9: 5 | B9: Transfered from APRF No. 513665. Requesting a Direct Voucher - Exhibit B for O'Hare due to expired contract. Elevators,1-MOD/Final 7/27/26 nt | C9: CHICAGO DEPARTMENT OF AVIATION | D9: 3 | E9: 2596967.8 | F9: 29297991 | G9: 0.55061792 | H9: D. Solicitation Response Under Evaluation | I9: Still open
A10: 6 | B10: PURCHASE OF BLACK AND BLUE MOBILE CARTS | C10: DEPARTMENT OF STREETS AND SANITATION | D10: 4 | E10: 2406381.5 | F10: 31704373 | G10: 0.59584276 | H10: C. Solicitation or Bidding Phase | I10: Still open
A11: 7 | B11: Street and Parkway Restoration Central North Region | C11: DEPARTMENT OF WATER MANAGEMENT | D11: 2 | E11: 1902848.1 | F11: 33607221 | G11: 0.63160433 | H11: H. One Time Purchase | I11: Claimed awarded - UNVERIFIED
A12: 8 | B12: FFIB Industrial Fence $578,668.60 | C12: CHICAGO FIRE DEPARTMENT | D12: 22 | E12: 1061040.1 | F12: 34668261 | G12: 0.65154521 | H12: B. City Law Review | I12: Still open
A13: 9 | B13: Street and Parkway Restoration North Region | C13: DEPARTMENT OF WATER MANAGEMENT | D13: 1 | E13: 938950.36 | F13: 35607211 | G13: 0.66919157 | H13: H. One Time Purchase | I13: Claimed awarded - UNVERIFIED
A14: 10 | B14: PROVIDE AN ELECTRICIANCUSTOMER, TROUBLESHOOTACCURPRESS AND BACK GAUGE FOROPERATION | C14: CHICAGO DEPARTMENT OF TRANSPORTATION | D14: 10 | E14: 891296.67 | F14: 36498508 | G14: 0.68594234 | H14: B. City Law Review | I14: Still open
A15: 11 | B15: There is currently no active contract for Integrated Pest Management. The vendor chose not to extend beyond the May 29, 2025 expiration date. 2FM subm | C15: DEPARTMENT OF FLEET AND FACILITY MANAGEMENT | D15: 21 | E15: 824511.78 | F15: 37323020 | G15: 0.70143797 | H15: A. Specification Development Phase | I15: Still open
A16: 12 | B16: Street and Parkway and Restoration Project No. 19-623 Central South Region | C16: DEPARTMENT OF WATER MANAGEMENT | D16: 1 | E16: 687712.68 | F16: 38010733 | G16: 0.71436265 | H16: H. One Time Purchase | I16: Claimed awarded - UNVERIFIED
... A69: 65 | B69: Landscape Services North & South LSD | C69: CHICAGO DEPARTMENT OF TRANSPORTATION | D69: 1 | E69: 76280.53 | F69: 51056420 | G69: 0.9595395 | H69: B. City Law Review | I69: Still open
A70: 66 | B70: Greater Illinois Title Company Invoices from Nov 2025 to Dec 2025 | C70: DEPARTMENT OF PLANNING AND DEVELOPMENT | D70: 4 | E70: 74125 | F70: 51130545 | G70: 0.96093258 | I70: Still open
A71: 67 | B71: 1 invoice for CDWG That was canceled by mistake after 2FM merged with IT and the PO invoice was cancel and was not paid. | C71: DEPARTMENT OF TECHNOLOGY AND INNOVATION | D71: 1 | E71: 69919.94 | F71: 51200465 | G71: 0.96224664 | H71: H. One Time Purchase | I71: Still open
A72: 68 | B72: Community Services, (Testing and Vaccine Services) December 2025 | C72: CHICAGO DEPARTMENT OF PUBLIC HEALTH | D72: 1 | E72: 69415.23 | F72: 51269880 | G72: 0.96355121 | H72: A. Specification Development Phase | I72: Still open
A73: 69 | B73: ELECTRICALPRODUCTS AND SUPPLIES | C73: CHICAGO DEPARTMENT OF TRANSPORTATION | D73: 1 | E73: 69314.85 | F73: 51339195 | G73: 0.96485389 | H73: B. City Law Review | I73: Still open
A74: 70 | B74: STUMP GRINDING | C74: DEPARTMENT OF STREETS AND SANITATION | D74: 2 | E74: 68173.46 | F74: 51407368 | G74: 0.96613512 | H74: D. Solicitation Response Under Evaluation | I74: Still open
A75: 71 | B75: EXHIBIT B - TALOGY PO 251333 INVOICES $67,689.70 | C75: DEPARTMENT OF HUMAN RESOURCES | D75: 1 | E75: 67689.7 | F75: 51475058 | G75: 0.96740726 | H75: A. Specification Development Phase | I75: Claimed awarded - UNVERIFIED
A76: 72 | B76: S&S Lead Dept. 2FM utilizes PO 92930 for the Purchase of Paint Products and Accessories. The contract expired on 3/7/25. S&S submitted a replaceme | C76: DEPARTMENT OF FLEET AND FACILITY MANAGEMENT | D76: 3 | E76: 67075.71 | F76: 51542134 | G76: 0.96866786 | H76: A. Specification Development Phase | I76: Still open
A77: 73 | B77: Chemical reagents and larvicideSurveillance fee | C77: CHICAGO DEPARTMENT OF PUBLIC HEALTH | D77: 1 | E77: 66126.92 | F77: 51608261 | G77: 0.96991063 | H77: H. One Time Purchase | I77: Still open
A78: 74 | B78: BOTTLED DRINKING WATER, DISTILLED WATER & WATER COOLER RENTALS | C78: CHICAGO DEPARTMENT OF TRANSPORTATION | D78: 27 | E78: 63682.14 | F78: 51671943 | G78: 0.97110746 | H78: A. Specification Development Phase | I78: Still open
A79: 75 | B79: eBicycle purchase for Parking Enforcement Aides | C79: DEPARTMENT OF FINANCE | D79: 1 | E79: 61200 | F79: 51733143 | G79: 0.97225763 | H79: H. One Time Purchase | I79: Still open
A80: 76 | B80: PRINTING EQUIPMENT | C80: DEPARTMENT OF LAW | D80: 1 | E80: 60771.56 | F80: 51793914 | G80: 0.97339976 | H80: C. Solicitation or Bidding Phase | I80: Still open
A81: 77 | B81: Community Testing, Infection Prevention | C81: CHICAGO DEPARTMENT OF PUBLIC HEALTH | D81: 2 | E81: 60732.8 | F81: 51854647 | G81: 0.97454115 | H81: A. Specification Development Phase | I81: Still open
A82: 78 | B82: Feb 2026 Waste Management Services at Midway. To pay Invoice # 55883 | C82: CHICAGO DEPARTMENT OF AVIATION | D82: 2 | E82: 58167.62 | F82: 51912815 | G82: 0.97563434 | H82: A. Specification Development Phase | I82: Still open
... A131: 127 | B131: TB/JM/INVOICE #3931/$4000.00 | C131: DEPARTMENT OF FLEET AND FACILITY MANAGEMENT | D131: 2 | E131: 8000 | F131: 53117002 | G131: 0.99826548 | H131: A. Specification Development Phase | I131: Still open
A132: 128 | B132: CoStar Aug 2026 Invoice | C132: DEPARTMENT OF PLANNING AND DEVELOPMENT | D132: 2 | E132: 7906.6 | F132: 53124909 | G132: 0.99841407 | I132: Still open
A133: 129 | B133: Specialized supplies for preservation project of City Council archival materials. | C133: OFFICE OF CITY CLERK | D133: 1 | E133: 7396.57 | F133: 53132305 | G133: 0.99855308 | H133: H. One Time Purchase | I133: Still open
A134: 130 | B134: #2 Invoices $7,082.00 Requesting a Direct Voucher - Exhibit B for Ohare to due VLI. A VLI extension has been requested. | C134: CHICAGO DEPARTMENT OF AVIATION | D134: 1 | E134: 7082 | F134: 53139387 | G134: 0.99868618 | H134: D. Solicitation Response Under Evaluation | I134: Still open
A135: 131 | B135: Sewer Construction | C135: DEPARTMENT OF WATER MANAGEMENT | D135: 1 | E135: 6839.9 | F135: 53146227 | G135: 0.99881473 | H135: H. One Time Purchase | I135: Still open
A136: 132 | B136: TB/GR/INV #5072349294/$6015.80 | C136: DEPARTMENT OF FLEET AND FACILITY MANAGEMENT | D136: 1 | E136: 6015.8 | F136: 53152243 | G136: 0.99892779 | H136: A. Specification Development Phase | I136: Still open
A137: 133 | B137: Canon Copier Services Contract in VLI process | C137: CHICAGO ANIMAL CARE AND CONTROL | D137: 1 | E137: 5595.97 | F137: 53157839 | G137: 0.99903295 | H137: A. Specification Development Phase | I137: Still open
A138: 134 | B138: Republic Service Inv# 0710-005914497 | C138: CHICAGO POLICE DEPARTMENT | D138: 1 | E138: 4891.34 | F138: 53162730 | G138: 0.99912488 | H138: A. Specification Development Phase | I138: Still open
A139: 135 | B139: All In One Desktops | C139: CHICAGO DEPARTMENT OF PUBLIC HEALTH | D139: 1 | E139: 4815 | F139: 53167545 | G139: 0.99921537 | H139: H. One Time Purchase | I139: Claimed awarded - UNVERIFIED
A140: 136 | B140: A VLI was submitted to DPS in October 2024 under Rx 623996. We held invoices for the past five months in anticipation of the VLI approval, in an effor | C140: DEPARTMENT OF FLEET AND FACILITY MANAGEMENT | D140: 1 | E140: 4492.25 | F140: 53172037 | G140: 0.9992998 | H140: F. SC - (Signature Cycle) | I140: Still open
A141: 137 | B141: LKP Legislative services | C141: OFFICE OF THE MAYOR | D141: 1 | E141: 4000 | F141: 53176037 | G141: 0.99937497 | H141: H. One Time Purchase | I141: Still open
...

Sheet Pipeline Forecast
A1: PIPELINE FORECAST - WHAT CONVERTS NEXT
A2: Procurement Phase shows how far each Exhibit B requisition has progressed toward a contract. This turns a backward-looking scorecard into a forecast.
A4: Procurement Phase | B4: Expected Conversion Horizon | C4: Sourcing Efforts | D4: Requisitions | E4: Exhibit B Spend | F4: Share of Spend
A5: (not stated) | B5: unknown | C5: 6 | D5: 11 | E5: 84466.95 | F5: 0.0015799617
A6: A. Specification Development Phase | B6: 12+ months | C6: 71 | D6: 357 | E6: 23024247 | F6: 0.43067055
A7: B. City Law Review | B7: 6-12 months | C7: 42 | D7: 182 | E7: 8176786.7 | F7: 0.15294751
A8: C. Solicitation or Bidding Phase | B8: 3-6 months | C8: 12 | D8: 33 | E8: 2991599.2 | F8: 0.055958124
A9: D. Solicitation Response Under Evaluation | B9: 3-6 months | C9: 16 | D9: 30 | E9: 3699094.1 | F9: 0.069191877
A10: E. ROA - (Recommendation of Award) | B10: 0-3 months - imminent | C10: 5 | D10: 12 | E10: 5044003.9 | F10: 0.094348532
A11: F. SC - (Signature Cycle) | B11: 0-3 months - imminent | C11: 9 | D11: 13 | E11: 3543380.8 | F11: 0.066279246
A12: G. Not Applicable (Office Depot use Only) | B12: n/a - not applicable | C12: 5 | D12: 7 | E12: 555173.71 | F12: 0.010384573
A13: H. One Time Purchase | B13: n/a - one-time purchase | C13: 56 | D13: 85 | E13: 6342640 | F13: 0.11863963
A14: TOTAL | E14: =SUM(E5:E13) | F14: =SUM(F5:F13)
A16: NEAR-TERM HEADLINE: 25 requisitions worth $8,587,385 are in Recommendation of Award or Signature Cycle - one administrative step from a contract. Expect these to leave Exhibit B within 60-90 days.

Sheet Reverse Leakage
A1: REVERSE LEAKAGE - EXHIBIT B FILED AFTER THE CONTRACT EXISTED
A2: These requisitions were processed as contract exceptions AFTER an award covering that scope had already landed. The spend should have ridden the contract.
A4: Exhibit B Req# | B4: Exhibit B Date | C4: Department | D4: Description | E4: Spend That Should Have Ridden Contract | F4: Contract Award Date | G4: Awarded Vendor | H4: Awarded Contract ID | I4: Days After Award
A5: 744483 | B5: 46241 | C5: DEPARTMENT OF TECHNOLOGY AND INNOVATION | D5: 1- 2025 unpaid DLT invoice for Oracle Active Data Guard Processor. This invoice was received after the Finance cutoff re | E5: 48673.35 | F5: 46073 | G5: DLT SOLUTIONS LLC | H5: 387728 | I5: 168
A6: 737833 | B6: 46203 | C6: DEPARTMENT OF FLEET AND FACILITY MANAGEMENT | D6: Helicopter Inc. 10633647 A JS/ BJ/ 2-Invoices/ $18,497.54/ PD911Q/ WO 2626555/ ASR/50 HR inspection due and 150 hr engi | E6: 18497.54 | F6: 46203 | G6: Helicopters, Inc. | H6: 386844 | I6: 0
A7: 742855 | B7: 46231 | C7: DEPARTMENT OF FAMILY AND SUPPORT SERVICES | D7: Exhibit B_2 8160 | E7: 8160 | F7: 46203 | G7: Service Sanitation Inc. | H7: 381051 | I7: 28
A8: 742832 | B8: 46238 | C8: DEPARTMENT OF FAMILY AND SUPPORT SERVICES | D8: Exhibit B_ 8160 | E8: 8160 | F8: 46203 | G8: Service Sanitation Inc. | H8: 381051 | I8: 35
A9: 742887 | B9: 46231 | C9: DEPARTMENT OF FAMILY AND SUPPORT SERVICES | D9: Exhibit B_3_7644 | E9: 7644 | F9: 46203 | G9: Service Sanitation Inc. | H9: 381051 | I9: 28
A10: 746639 | B10: 46253.939 | C10: OFFICE OF THE MAYOR | D10: LKP Legislative services | E10: 4000 | F10: 46024 | G10: LKP CONSULTING LLC | H10: 386406 | I10: 229
A11: 734820 | B11: 46182 | C11: CHICAGO DEPARTMENT OF AVIATION | D11: Invoice# SS109523 Sherwin Industries FAA Part 139 Regulatory Compliance. Calibration of AFM2 (8 units) and labor for | E11: 3916 | F11: 46106 | G11: Halliday Technologies | H11: 375509 | I11: 76
A12: 745303 | B12: 46246 | C12: CHICAGO DEPARTMENT OF PUBLIC HEALTH | D12: OES:Odysseus Licensing FeeAnnual Licensing and Hosting Fee: June 2026 | E12: 833 | F12: 46220 | G12: INTEGRATED SOLUTIONS CONSULTING CORPORATION | H12: 386925 | I12: 26

Sheet Data Quality Findings
A1: DATA QUALITY FINDINGS
A2: Issues in the source data that limit measurement - and that are fixable at the point of entry.
A4: Finding | B4: Detail | C4: Impact on Measurement | D4: Recommended Fix
A5: 'Contract Number Awarded' is largely unusable | B5: 136 of 221 populated values are not contract numbers - they include 'TBD', 'na', '0', 'NO', 'yes', 'Pending', 'UNKNOWN', 'N?A' and 'None yet'. | C5: Cannot verify an award from this field alone | D5: Make it a validated numeric field, required only when 'Contract Awarded?' = Yes
A6: Claimed contract numbers do not reconcile | B6: 25 distinct numbers were supplied on rows claiming an award. Only 2 appear anywhere in the awarded contract file. | C6: The award claim cannot be substantiated for most rows | D6: Validate the entry against the contract master at the point of entry
A7: 'Requisition# for New Contract/Mod' is free text | B7: 91 of 654 values need parsing - 'RX 596048', 'RX676831- SPEC 1197406C', concatenated '710856710875', 'Target Market 710856, Non-Target Market 710875', 'na'. | C7: Automated tracking requires a cleanup pass every time | D7: Split into a numeric requisition field plus a free-text note field
A8: Awarded contract file has no requisition on every row | B8: 14 of 100 awarded contracts carry no REQ number, and 0 carry no SPEC. | C8: Those awards cannot be traced back to the Exhibit B that preceded them | D8: Require the originating requisition on every award record
A9: No shared key between the two systems | B9: Exhibit B and the award file share no reliable common identifier; linkage depends on requisition numbers appearing in a free-text field. | C9: Conversion cannot be measured automatically today | D9: Carry the Exhibit B requisition number forward onto the resulting award record

Sheet Methodology & Limits
A1: METHODOLOGY, DEFINITIONS AND LIMITATIONS
A2: Read this before quoting any number in this workbook.
B4: WHAT THIS ANALYSIS ANSWERS
B5: Question | C5: Did non-contract ('maverick') Exhibit B spend move onto a competitively awarded contract during the period?
B6: Two gates | C6: Gate 1 - did the spend exit Exhibit B onto an awarded contract? Gate 2 - was that award competitive (Bid/RFQ/RFP)? Exiting Exhibit B into a sole-source or emergency award clears the exception report but is not the procurement-correct outcome.
B8: UNIT OF ANALYSIS
B9: Sourcing effort | C9: Requisitions are rolled up to the pending new-contract requisition (RX). 730 Exhibit B requisitions represent only 175 distinct sourcing efforts. One effort absorbs 49 requisitions and $16,275,951. Counting requisitions overstates the number of problems and understates their size.
B11: EVIDENCE TIERS
B12: Tier A - Confirmed | C12: Hard ID link: the Exhibit B new-contract requisition equals an awarded REQ, or the reported contract number equals an awarded PO/CONTRACT_ID.
B13: Tier B - Confirmed | C13: Same vendor plus commodity-token overlap of 10% or more between the Exhibit B description and the award description.
B14: Tier C - Suggestive | C14: Same vendor only, no commodity overlap. NOT counted as a conversion.
B15: Tier D - Weak | C15: Description similarity of 30% or more with no vendor or ID link. NOT counted as a conversion.
B16: Tier E - None | C16: No linkage found in the awarded contract file.
B17: Timing gate | C17: A Tier A or B match counts as a conversion only if the award date is AFTER the Exhibit B date. A match with an earlier award date is reverse leakage, not a conversion.
B18: Headline basis | C18: The headline conversion figure uses Tier A and B only. Tiers C and D are disclosed separately and are never added to the headline.
B20: DENOMINATOR
B21: Expected to convert | C21: 'Request for New Contract/Mod' = Yes, excluding justifications 3. One Time Purchase, 4. Invoice Reconciliation, 6. Bid Protest - these are not intended to result in a contract. 476 requisitions ($40,335,240) meet this test.
B23: LIMITATIONS - READ BEFORE CITING
B24: Award file is a fixed list | C24: The awarded contract file contains 100 contracts. If it is not the complete population of awards for the period, an Exhibit B effort could have been awarded on a contract absent from this file. 'No verified conversion' therefore means 'not evidenced in the supplied award data' - it does not prove no award occurred.
B25: No shared key | C25: The two systems share no reliable common identifier. Linkage depends on requisition numbers appearing inside a free-text field, so some genuine conversions are likely unmatched. The verified figure is a floor, not a ceiling.
B26: Self-reported fields excluded | C26: 'Contract Awarded?' and 'Contract Number Awarded' are department self-reports and are analysed as a claim to be tested, never used as evidence of conversion.
B27: Spend basis | C27: Requisition Amount as submitted. Approved and denied rows are both retained in the population and flagged; denied rows never count as converted.
B28: Period | C28: January 5, 2026 to August 20, 2026. Both tabs cover the same window, so an Exhibit B request late in the period has had little time to reach award - conversion for recent months is understated by construction.
B30: SOURCE DATA
B31: Exhibit B tab | C31: 730 requisitions, $53,461,392.14
B32: Awarded contracts tab | C32: 100 contracts, $2,591,929,537.52 total award value (full award book, not only Exhibit B conversions)
B33: Competitive definition | C33: PROCUREMENT_TYPE in ['BID', 'RFP', 'RFQ']. 53 of 100 awards qualify.

Sheet EB Detail
A1: Requisition Number | B1: Exhibit B Date | C1: Department | D1: Vendor | E1: Description | F1: Amount | G1: Justification | H1: Procurement Phase | I1: Approved or Denied | J1: New Contract Requested | K1: Self-Reported Awarded | L1: Contract # Claimed | M1: Sourcing Key | N1: Evidence Tier | O1: Match Basis | P1: Awarded Contract ID | Q1: Awarded Vendor | R1: Award Date | S1: Procurement Type | T1: Competitive | U1: Converted | V1: Reverse Leak | W1: Expected to Convert
A2: 737798 | B2: 46203 | C2: DEPARTMENT OF WATER MANAGEMENT | D2: PAN-OCEANIC ENGINEERING CO INC | E2: Sewer Construction | F2: 121426.74 | G2: 1. Pending New Contract - Original Contract Expired. New Contract in Process | H2: H. One Time Purchase | I2: APPROVED | J2: Yes | K2: Yes | L2: 297413 | M2: VDPAN OCEANIC ENGINEERING | N2: E | O2: No linkage found in awarded contract file | T2: No | U2: No | V2: No | W2: Yes
A3: 734966 | B3: 46182 | C3: DEPARTMENT OF WATER MANAGEMENT | D3: SEVEN D CONSTRUCTION COMPANY | E3: Street and Parkway Repair Project NO. 19-625 North Region | F3: 143357.36 | G3: 1. Pending New Contract - Original Contract Expired. New Contract in Process | H3: H. One Time Purchase | I3: APPROVED | J3: Yes | K3: Yes | L3: 272860 | M3: RX492769 | N3: C | O3: Vendor name match only (similarity 0.00) | P3: 383513 | Q3: SEVEN D CONSTRUCTION COMPANY | R3: 46107 | S3: BID | T3: Yes | U3: No | V3: No | W3: Yes
A4: 741608 | B4: 46223 | C4: DEPARTMENT OF WATER MANAGEMENT | D4: CHARLES EQUIPMENT ENERGY SYSTEMS LLC | E4: Perform 2025 annual planned maintenance on one Caterpillar chlorine emergency power generator and five MTU main plant power emergency generators | F4: 33822.1 | G4: 1. Pending New Contract - Original Contract Expired. New Contract in Process | H4: H. One Time Purchase | I4: APPROVED | J4: Yes | K4: No | M4: RX622326 | N4: E | O4: No linkage found in awarded contract file | T4: No | U4: No | V4: No | W4: Yes
A5: 742464 | B5: 46226 | C5: DEPARTMENT OF FLEET AND FACILITY MANAGEMENT | D5: JACOB PRESS' SONS INC | E5: WB/MM/INVOICE#598412/$1221.66 | F5: 1221.66 | G5: 1. Pending New Contract - Original Contract Expired. New Contract in Process | H5: B. City Law Review | I5: DENIED | J5: Yes | K5: No | M5: RX590958 | N5: E | O5: No linkage found in awarded contract file | T5: No | U5: No | V5: No | W5: Yes
A6: 726600 | B6: 46146 | C6: DEPARTMENT OF BUSINESS AFFAIRS AND CONSUMER PROTECTION | D6: WALZ SCALES CO. | E6: SCALES CERTIFICATION | F6: 980 | G6: 3. One Time Purchase | H6: H. One Time Purchase | I6: APPROVED | J6: Yes | K6: No | M6: VDWALZ SCALES | N6: E | O6: No linkage found in awarded contract file | T6: No | U6: No | V6: No | W6: No
A7: 742345 | B7: 46226 | C7: CHICAGO FIRE DEPARTMENT | D7: ACORN GARAGE INC | E7: INV#204824 | F7: 273 | G7: 1. Pending New Contract - Original Contract Expired. New Contract in Process | H7: H. One Time Purchase | I7: DENIED | J7: No | K7: No | M7: RX680611 | N7: E | O7: No linkage found in awarded contract file | T7: No | U7: No | V7: No | W7: No
A8: 739577 | B8: 46210 | C8: CHICAGO FIRE DEPARTMENT | D8: TELEFLEX LLC | E8: QUOTE#0578146 | F8: 1735 | G8: 1. Pending New Contract - Original Contract Expired. New Contract in Process | H8: A. Specification Development Phase | I8: DENIED | J8: Yes | K8: No | M8: RX695898 | N8: E | O8: No linkage found in awarded contract file | T8: No | U8: No | V8: No | W8: Yes
A9: 707111 | B9: 46027 | C9: DEPARTMENT OF BUILDINGS | D9: A & D PROPERTY SERVICES, INC. | E9: BOARD UP SERVICES | F9: 38700 | G9: 1. Pending New Contract - Original Contract Expired. New Contract in Process | H9: A. Specification Development Phase | I9: APPROVED | J9: Yes | K9: No | L9: 32040 | M9: RX659422 | N9: E | O9: No linkage found in awarded contract file | T9: No | U9: No | V9: No | W9: Yes
A10: 718143 | B10: 46087 | C10: DEPARTMENT OF BUILDINGS | D10: A & D PROPERTY SERVICES, INC. | E10: BOARD UP SERVICES | F10: 43650 | G10: 1. Pending New Contract - Original Contract Expired. New Contract in Process | H10: B. City Law Review | I10: APPROVED | J10: Yes | K10: No | L10: 32040 | M10: RX659422 | N10: E | O10: No linkage found in awarded contract file | T10: No | U10: No | V10: No | W10: Yes
A11: 716026 | B11: 46078 | C11: OFFICE OF THE MAYOR | D11: Berlin Rosen, LLC | E11: Berlin Rosen Public relations Nov/Dec 2025 | F11: 9975.75 | G11: 3. One Time Purchase | H11: H. One Time Purchase | I11: APPROVED | J11: No | K11: No | L11: none | M11: VDBERLIN ROSEN | N11: E | O11: No linkage found in awarded contract file | T11: No | U11: No | V11: No | W11: No
A12: 745000 | B12: 46245 | C12: DEPARTMENT OF FLEET AND FACILITY MANAGEMENT | D12: P. R. STREICH & SONS | E12: KB/MM/ INV#56736/ $693.39 | F12: 693.39 | G12: 1. Pending New Contract - Original Contract Expired. New Contract in Process | H12: B. City Law Review | I12: APPROVED | J12: Yes | K12: No | L12: TBD | M12: RX679901 | N12: E | O12: No linkage found in awarded contract file | T12: No | U12: No | V12: No | W12: Yes
A13: 708310 | B13: 46035 | C13: CHICAGO DEPARTMENT OF PUBLIC HEALTH | D13: CIS Support, Inc. | E13: CIS Maintenance/Support-December | F13: 5500 | G13: 1. Pending New Contract - Original Contract Expired. New Contract in Process | H13: H. One Time Purchase | I13: APPROVED | J13: Yes | K13: No | M13: VDCIS SUPPORT | N13: E | O13: No linkage found in awarded contract file | T13: No | U13: No | V13: No | W13: Yes
A14: 707519 | B14: 46031 | C14: DEPARTMENT OF WATER MANAGEMENT | D14: USALCO | E14: Liquid Aluminum Sulfate (Iron Free) | F14: 663663.84 | G14: 1. Pending New Contract - Original Contract Expired. New Contract in Process | H14: A. Specification Development Phase | I14: APPROVED | J14: Yes | K14: No | M14: RX661351 | N14: E | O14: No linkage found in awarded contract file | T14: No | U14: No | V14: No | W14: Yes
A15: 737495 | B15: 46197 | C15: CHICAGO FIRE DEPARTMENT | D15: INDUSTRIAL FENCE INC. | E15: FFIB Industrial Fence $578,668.60 | F15: 578668.6 | G15: 1. Pending New Contract - Original Contract Expired. New Contract in Process | H15: B. City Law Review | I15: DENIED | J15: No | K15: No | M15: RX596048 | N15: E | O15: No linkage found in awarded contract file | T15: No | U15: No | V15: No | W15: No
A16: 740144 | B16: 46220 | C16: DEPARTMENT OF FAMILY AND SUPPORT SERVICES | D16: DIRECT FITNESS SOLUTIONS, LLC | E16: Aps 82_Fitness Equipment Maintenance Project | F16: 0 | G16: 1. Pending New Contract - Original Contract Expired. New Contract in Process | H16: A. Specification Development Phase | I16: APPROVED | J16: No | K16: No | M16: RX609670 | N16: E | O16: No linkage found in awarded contract file | T16: No | U16: No | V16: No | W16: No
A17: 709818 | B17: 46044 | C17: DEPARTMENT OF FLEET AND FACILITY MANAGEMENT | D17: RUNNION EQUIPMENT CO | E17: We currently do not have a contract in place due to City Utility (PO # 17836) no longer performing this work for us. These aerial bucket trucks are used by CDOT (street light and traffic signal installation and repair), Streets & Sanitation | F17: 6681 | G17: 1. Pending New Contract - Original Contract Expired. New Contract in Process | H17: B. City Law Review | I17: APPROVED | J17: Yes | K17: No | M17: RX590958 | N17: E | O17: No linkage found in awarded contract file | T17: No | U17: No | V17: No | W17: Yes
A18: 728640 | B18: 46146 | C18: DEPARTMENT OF FLEET AND FACILITY MANAGEMENT | D18: RUNNION EQUIPMENT CO | E18: We currently do not have a contract in place due to City Utility (PO # 17836) no longer performing this work for us. These aerial bucket trucks are used by CDOT (street light and traffic signal installation and repair), Streets & Sanitation | F18: 9754.65 | G18: 1. Pending New Contract - Original Contract Expired. New Contract in Process | H18: B. City Law Review | I18: APPROVED | J18: Yes | K18: No | M18: RX590958 | N18: E | O18: No linkage found in awarded contract file | T18: No | U18: No | V18: No | W18: Yes
A19: 738075 | B19: 46203 | C19: DEPARTMENT OF FLEET AND FACILITY MANAGEMENT | D19: BELLA BAGNO INC | E19: Bella Bagno Inc is removing and installing carpet at the Bucktown/Wicker Park Branch Library. The labor services are outside of the contract prevue, and should be paid under Exhibit B. CDA has a new solicitation for purchase and installatio | F19: 147666.41 | G19: 1. Pending New Contract - Original Contract Expired. New Contract in Process | H19: D. Solicitation Response Under Evaluation | I19: APPROVED | J19: Yes | K19: Yes | M19: RX628102 | N19: E | O19: No linkage found in awarded contract file | T19: No | U19: No | V19: No | W19: Yes
A20: 728179 | B20: 46142 | C20: DEPARTMENT OF FLEET AND FACILITY MANAGEMENT | D20: P. R. STREICH & SONS | E20: There is curently no active contract with a vendor to repair and certify the shop floor equipment. Our previous vendor, Standard Industrial (PO 24519) did not want to extend their contract. Due to this 2FM found a local vendor PR Streich to | F20: 925 | G20: 1. Pending New Contract - Original Contract Expired. New Contract in Process | H20: B. City Law Review | I20: APPROVED | J20: Yes | K20: No | L20: TBD | M20: RX679901 | N20: E | O20: No linkage found in awarded contract file | T20: No | U20: No | V20: No | W20: Yes
A21: 721747 | B21: 46107 | C21: DEPARTMENT OF FLEET AND FACILITY MANAGEMENT | D21: Service Sanitation Inc. | E21: DCASE submitted a new contract request for RENTAL AND MAINTENANCE OF PORTABLE CHEMICAL TOILETS, SINKS, WASTE WATER BARRELS, PORTABLE WATERLESS HAND SANITIZER DISPENSERS, FRESH WATER TRAILER AND PORTABLE SHOWERS to DPS under RX 613315, Spec | F21: 247.5 | G21: 1. Pending New Contract - Original Contract Expired. New Contract in Process | H21: D. Solicitation Response Under Evaluation | I21: APPROVED | J21: Yes | K21: No | M21: RX700212 | N21: B | O21: Vendor match + commodity overlap (similarity 0.64) | P21: 381051 | Q21: Service Sanitation Inc. | R21: 46203 | S21: BID | T21: Yes | U21: Yes | V21: No | W21: Yes
